<?xml version="1.0" encoding="utf-8"?>
<robot name="antt_t1">
  <link name="world"/>

  <link name="tbar_link">
    <inertial>
      <origin xyz="0 0 0" rpy="0 0 0"/>
      <mass value="0.1"/>
      <inertia ixx="1e-4" ixy="0" ixz="0" iyy="1e-4" iyz="0" izz="1e-4"/>
    </inertial>
    <visual>
      <origin xyz="0 0 0" rpy="0 0 0"/>
      <geometry>
        <box size="0.15 0.08 0.06"/>
      </geometry>
    </visual>
    <visual>
      <origin xyz="0 0 -0.60" rpy="0 0 0"/>
      <geometry>
        <box size="0.08 0.08 1.20"/>
      </geometry>
    </visual>
    <collision>
      <origin xyz="0 0 0" rpy="0 0 0"/>
      <geometry>
        <box size="0.15 0.08 0.06"/>
      </geometry>
    </collision>
    <collision>
      <origin xyz="0 0 -0.60" rpy="0 0 0"/>
      <geometry>
        <box size="0.08 0.08 1.20"/>
      </geometry>
    </collision>
  </link>

  <joint name="world_to_tbar" type="fixed">
    <parent link="world"/>
    <child link="tbar_link"/>
    <origin xyz="0 0 1.2" rpy="0 0 0"/>
  </joint>

  <!-- Mount arms at horizontal beam ends (beam length 0.15 m => half-length 0.075 m) -->
  <joint name="tbar_to_left_base" type="fixed">
    <parent link="tbar_link"/>
    <child link="left_base_link"/>
    <origin xyz="0.075 0 0" rpy="1.5707963267948966 -1.5707963267948966 1.5707963267948966"/>
  </joint>

  <joint name="tbar_to_right_base" type="fixed">
    <parent link="tbar_link"/>
    <child link="right_base_link"/>
    <origin xyz="-0.075 0 0" rpy="1.5707963267948966 -1.5707963267948966 -1.5707963267948966"/>
  </joint>

    <link name="left_base_link">
        <inertial>
            <origin xyz="-0.00963614954335565 0.00016786624100977 0.044860101664403" rpy="0 0 0"/>
            <mass value="0.77"/>
            <inertia ixx="0.0006669" ixy="0.0" ixz="0.0" iyy="0.00054501" iyz="0.0" izz="0.00051509"/>
        </inertial>
        <visual>
            <origin xyz="0 0 0" rpy="0 0 0"/>
            <geometry>
                <mesh filename="package://nero_description/meshes/dae/base_link.dae"/>
            </geometry>
        </visual>
        <collision>
            <origin xyz="0 0 0" rpy="0 0 0"/>
            <geometry>
                <mesh filename="package://nero_description/meshes/base_link.STL"/>
            </geometry>
        </collision>
    </link>
    <link name="left_link1">
        <inertial>
            <origin xyz="-0.00077 -0.00006 -0.00686" rpy="0 0 0"/>
            <mass value="0.77"/>
            <inertia ixx="0.0006669" ixy="0.0" ixz="0.0" iyy="0.00054501" iyz="0.0" izz="0.00051509"/>
        </inertial>
        <visual>
            <origin xyz="0 0 0" rpy="0 0 0"/>
            <geometry>
                <mesh filename="package://nero_description/meshes/dae/link1.dae"/>
            </geometry>
        </visual>
        <collision>
            <origin xyz="0 0 0" rpy="0 0 0"/>
            <geometry>
                <mesh filename="package://nero_description/meshes/Link1.STL"/>
            </geometry>
        </collision>
    </link>
    <joint name="left_joint1" type="revolute">
        <origin xyz="0 0 0.138" rpy="0 0 0"/>
        <parent link="left_base_link"/>
        <child link="left_link1"/>
        <axis xyz="0 0 1"/>
        <limit lower="-2.7" upper="2.7" effort="0" velocity="0"/>
    </joint>
    <link name="left_link2">
        <inertial>
            <origin xyz="-0.00011 -0.06072 0.00148" rpy="0 0 0"/>
            <mass value="0.49"/>
            <inertia ixx="0.00053808" ixy="0.0" ixz="0.0" iyy="0.00029435" iyz="0.0" izz="0.00040266"/>
        </inertial>
        <visual>
            <origin xyz="0 0 0" rpy="0 0 0"/>
            <geometry>
                <mesh filename="package://nero_description/meshes/dae/link2.dae"/>
            </geometry>
        </visual>
        <collision>
            <origin xyz="0 0 0" rpy="0 0 0"/>
            <geometry>
                <mesh filename="package://nero_description/meshes/Link2.STL"/>
            </geometry>
        </collision>
    </link>
    <joint name="left_joint2" type="revolute">
        <origin xyz="0 0 0" rpy="1.5708 3.1415 0"/>
        <parent link="left_link1"/>
        <child link="left_link2"/>
        <axis xyz="0 0 1"/>
        <limit lower="-1.74" upper="1.74" effort="0" velocity="0"/>
    </joint>
    <link name="left_link3">
        <inertial>
            <origin xyz="0.00014 0.00211 -0.04853" rpy="0 0 0"/>
            <mass value="0.67"/>
            <inertia ixx="0.00342528" ixy="0.0" ixz="0.0" iyy="0.0033924" iyz="0.0" izz="0.00026169"/>
        </inertial>
        <visual>
            <origin xyz="0 0 0" rpy="0 0 0"/>
            <geometry>
                <mesh filename="package://nero_description/meshes/dae/link3.dae"/>
            </geometry>
        </visual>
        <collision>
            <origin xyz="0 0 0" rpy="0 0 0"/>
            <geometry>
                <mesh filename="package://nero_description/meshes/Link3.STL"/>
            </geometry>
        </collision>
    </link>
    <joint name="left_joint3" type="revolute">
        <origin xyz="0 -0.31 0" rpy="-1.5708 0 3.1416"/>
        <parent link="left_link2"/>
        <child link="left_link3"/>
        <axis xyz="0 0 1"/>
        <limit lower="-2.75" upper="2.75" effort="0" velocity="0"/>
    </joint>
    <link name="left_link4">
        <inertial>
            <origin xyz="-0.00013 -0.05482 0.00132" rpy="0 0 0"/>
            <mass value="0.41"/>
            <inertia ixx="0.00031331" ixy="0.0" ixz="0.0" iyy="0.00013204" iyz="0.0" izz="0.0002393"/>
        </inertial>
        <visual>
            <origin xyz="0 0 0" rpy="0 0 0"/>
            <geometry>
                <mesh filename="package://nero_description/meshes/dae/link4.dae"/>
            </geometry>
        </visual>
        <collision>
            <origin xyz="0 0 0" rpy="0 0 0"/>
            <geometry>
                <mesh filename="package://nero_description/meshes/Link4.STL"/>
            </geometry>
        </collision>
    </link>
    <joint name="left_joint4" type="revolute">
        <origin xyz="0 0 0" rpy="-1.5708 0 3.1416"/>
        <parent link="left_link3"/>
        <child link="left_link4"/>
        <axis xyz="0 0 1"/>
        <limit lower="-1.01" upper="2.14" effort="0" velocity="0"/>
    </joint>
    <link name="left_link5">
        <inertial>
            <origin xyz="0.00303 0.00617 -0.11778" rpy="0 0 0"/>
            <mass value="0.56"/>
            <inertia ixx="0.0008249" ixy="0.0" ixz="0.0" iyy="0.00078548" iyz="0.0" izz="0.00021015"/>
        </inertial>
        <visual>
            <origin xyz="0 0 0" rpy="0 0 0"/>
            <geometry>
                <mesh filename="package://nero_description/meshes/dae/link5.dae"/>
            </geometry>
        </visual>
        <collision>
            <origin xyz="0 0 0" rpy="0 0 0"/>
            <geometry>
                <mesh filename="package://nero_description/meshes/Link5.STL"/>
            </geometry>
        </collision>
    </link>
    <joint name="left_joint5" type="revolute">
        <origin xyz="0 -0.27001 0" rpy="1.5708 -1.5708 0"/>
        <parent link="left_link4"/>
        <child link="left_link5"/>
        <axis xyz="0 0 1"/>
        <limit lower="-2.75" upper="2.75" effort="0" velocity="0"/>
    </joint>
    <link name="left_link6">
        <inertial>
            <origin xyz="0.00014 -0.0027 -0.00025" rpy="0 0 0"/>
            <mass value="0.31"/>
            <inertia ixx="0.00008181" ixy="0.0" ixz="0.0" iyy="0.00007176" iyz="0.0" izz="0.00007906"/>
        </inertial>
        <visual>
            <origin xyz="0 0 0" rpy="0 0 0"/>
            <geometry>
                <mesh filename="package://nero_description/meshes/dae/link6.dae"/>
            </geometry>
        </visual>
        <collision>
            <origin xyz="0 0 0" rpy="0 0 0"/>
            <geometry>
                <mesh filename="package://nero_description/meshes/Link6.STL"/>
            </geometry>
        </collision>
    </link>
    <joint name="left_joint6" type="revolute">
        <origin xyz="0 0 0" rpy="1.5708 -1.5708 0"/>
        <parent link="left_link5"/>
        <child link="left_link6"/>
        <axis xyz="0 0 1"/>
        <limit lower="-0.73" upper="0.95" effort="0" velocity="0"/>
    </joint>
    <link name="left_link7">
        <inertial>
            <origin xyz="-0.00014000 -0.00010000 -0.00275000" rpy="0 0 0"/>
            <mass value="0.000001"/>
            <inertia ixx="1.1000000000000001e-07" ixy="0" ixz="0" iyy="1.1000000000000001e-07" iyz="0" izz="1.9999999999999999e-07"/>
        </inertial>
        <visual>
            <origin xyz="0 0 0" rpy="0 0 0"/>
            <geometry>
                <mesh filename="package://nero_description/meshes/dae/link7.dae"/>
            </geometry>
        </visual>
        <collision>
            <origin xyz="0 0 0" rpy="0 0 0"/>
            <geometry>
                <mesh filename="package://nero_description/meshes/Link7.STL"/>
            </geometry>
        </collision>
    </link>
    <joint name="left_joint7" type="revolute">
        <origin xyz="0 -0.0235 0" rpy="1.5708 0 0"/>
        <parent link="left_link6"/>
        <child link="left_link7"/>
        <axis xyz="0 0 1"/>
        <limit lower="-1.57" upper="1.57" effort="0" velocity="0"/>
    </joint>
    <link name="left_link8">
        <inertial>
            <origin xyz="-0.01208 -0.00025 0.00032" rpy="0 0 0"/>
            <mass value="0.05"/>
            <inertia ixx="2.697e-05" ixy="0" ixz="0" iyy="4.311e-05" iyz="0" izz="2.479e-05"/>
        </inertial>
        <visual>
            <origin xyz="0 0 0" rpy="-1.57 -1.57 -1.57"/>
            <geometry>
                <mesh filename="package://nero_description/meshes/stand_v1.dae"/>
            </geometry>
        </visual>
        <collision>
            <origin xyz="0 0 0" rpy="-1.57 -1.57 -1.57"/>
            <geometry>
                <mesh filename="package://nero_description/meshes/stand_v1.dae"/>
            </geometry>
        </collision>
    </link>
    <joint name="left_joint8" type="fixed">
        <origin xyz="0.033 0.00000000 -0.02350000" rpy="0 0 0"/>
        <parent link="left_link7"/>
        <child link="left_link8"/>
    </joint>

    <!-- Left Gripper Flange -->
    <link name="left_gripper_flange">
        <inertial>
            <origin xyz="0.0 0.0 -0.00032" rpy="0 0 0"/>
            <mass value="0.04771096"/>
            <inertia ixx="2.697e-05" ixy="0" ixz="0" iyy="4.311e-05" iyz="0" izz="2.479e-05"/>
        </inertial>
        <visual>
            <origin xyz="0 0 0" rpy="0 0 0"/>
            <geometry>
                <mesh filename="meshes/dae/gripper_flange.dae"/>
            </geometry>
        </visual>
        <collision>
            <origin xyz="0 0 0" rpy="0 0 0"/>
            <geometry>
                <mesh filename="meshes/gripper_flange.stl"/>
            </geometry>
        </collision>
    </link>
    <joint name="left_gripper_flange_joint" type="fixed">
        <origin xyz="0.032 0 -0.0235" rpy="-1.5708 0 -1.5708"/>
        <parent link="left_link7"/>
        <child link="left_gripper_flange"/>
    </joint>

    <!-- Left Gripper Base -->
    <link name="left_gripper_base">
        <inertial>
            <origin xyz="-0.000183807162235591 8.05033155577911E-05 0.0321436689908876" rpy="0 0 0"/>
            <mass value="0.45"/>
            <inertia ixx="0.00092934" ixy="0.00000034" ixz="-0.00000738" iyy="0.00071447" iyz="0.00000005" izz="0.00039442"/>
        </inertial>
        <visual>
            <origin xyz="0 0 0" rpy="0 0 0"/>
            <geometry>
                <mesh filename="meshes/dae/gripper_base.dae"/>
            </geometry>
        </visual>
        <collision>
            <origin xyz="0 0 0" rpy="0 0 0"/>
            <geometry>
                <mesh filename="meshes/gripper_base.stl"/>
            </geometry>
        </collision>
    </link>
    <joint name="left_gripper_base_joint" type="fixed">
        <origin xyz="0 0 0.0055" rpy="0 0 0"/>
        <parent link="left_gripper_flange"/>
        <child link="left_gripper_base"/>
    </joint>

    <!-- Left Gripper Link 1 -->
    <link name="left_gripper_link1">
        <inertial>
            <origin xyz="0.00065123185041968 -0.0491929869131989 0.00972258769184025" rpy="0 0 0"/>
            <mass value="0.025"/>
            <inertia ixx="0.00007371" ixy="-0.00000113" ixz="0.00000021" iyy="0.00000781" iyz="-0.00001372" izz="0.0000747"/>
        </inertial>
        <visual>
            <origin xyz="0 0 0" rpy="0 0 0"/>
            <geometry>
                <mesh filename="meshes/dae/gripper_link1.dae"/>
            </geometry>
        </visual>
        <collision>
            <origin xyz="0 0 0" rpy="0 0 0"/>
            <geometry>
                <mesh filename="meshes/gripper_link1.stl"/>
            </geometry>
        </collision>
    </link>
    <joint name="left_gripper_joint1" type="prismatic">
        <origin xyz="0 0 0.1358" rpy="1.5707963 0 3.1415926"/>
        <parent link="left_gripper_base"/>
        <child link="left_gripper_link1"/>
        <axis xyz="0 0 1"/>
        <limit lower="0" upper="0.05" effort="10" velocity="3"/>
    </joint>

    <!-- Left Gripper Link 2 -->
    <link name="left_gripper_link2">
        <inertial>
            <origin xyz="0.00065123185041968 -0.0491929869131989 0.00972258769184025" rpy="0 0 0"/>
            <mass value="0.025"/>
            <inertia ixx="0.00007371" ixy="-0.00000113" ixz="0.00000021" iyy="0.00000781" iyz="-0.00001372" izz="0.0000747"/>
        </inertial>
        <visual>
            <origin xyz="0 0 0" rpy="0 0 0"/>
            <geometry>
                <mesh filename="meshes/dae/gripper_link2.dae"/>
            </geometry>
        </visual>
        <collision>
            <origin xyz="0 0 0" rpy="0 0 0"/>
            <geometry>
                <mesh filename="meshes/gripper_link2.stl"/>
            </geometry>
        </collision>
    </link>
    <joint name="left_gripper_joint2" type="prismatic">
        <origin xyz="0 0 0.1358" rpy="1.5707963 0 0"/>
        <parent link="left_gripper_base"/>
        <child link="left_gripper_link2"/>
        <axis xyz="0 0 -1"/>
        <limit lower="-0.05" upper="0" effort="10" velocity="3"/>
    </joint>

    <link name="right_base_link">
        <inertial>
            <origin xyz="-0.00963614954335565 0.00016786624100977 0.044860101664403" rpy="0 0 0"/>
            <mass value="0.77"/>
            <inertia ixx="0.0006669" ixy="0.0" ixz="0.0" iyy="0.00054501" iyz="0.0" izz="0.00051509"/>
        </inertial>
        <visual>
            <origin xyz="0 0 0" rpy="0 0 0"/>
            <geometry>
                <mesh filename="package://nero_description/meshes/dae/base_link.dae"/>
            </geometry>
        </visual>
        <collision>
            <origin xyz="0 0 0" rpy="0 0 0"/>
            <geometry>
                <mesh filename="package://nero_description/meshes/base_link.STL"/>
            </geometry>
        </collision>
    </link>
    <link name="right_link1">
        <inertial>
            <origin xyz="-0.00077 -0.00006 -0.00686" rpy="0 0 0"/>
            <mass value="0.77"/>
            <inertia ixx="0.0006669" ixy="0.0" ixz="0.0" iyy="0.00054501" iyz="0.0" izz="0.00051509"/>
        </inertial>
        <visual>
            <origin xyz="0 0 0" rpy="0 0 0"/>
            <geometry>
                <mesh filename="package://nero_description/meshes/dae/link1.dae"/>
            </geometry>
        </visual>
        <collision>
            <origin xyz="0 0 0" rpy="0 0 0"/>
            <geometry>
                <mesh filename="package://nero_description/meshes/Link1.STL"/>
            </geometry>
        </collision>
    </link>
    <joint name="right_joint1" type="revolute">
        <origin xyz="0 0 0.138" rpy="0 0 0"/>
        <parent link="right_base_link"/>
        <child link="right_link1"/>
        <axis xyz="0 0 1"/>
        <limit lower="-2.7" upper="2.7" effort="0" velocity="0"/>
    </joint>
    <link name="right_link2">
        <inertial>
            <origin xyz="-0.00011 -0.06072 0.00148" rpy="0 0 0"/>
            <mass value="0.49"/>
            <inertia ixx="0.00053808" ixy="0.0" ixz="0.0" iyy="0.00029435" iyz="0.0" izz="0.00040266"/>
        </inertial>
        <visual>
            <origin xyz="0 0 0" rpy="0 0 0"/>
            <geometry>
                <mesh filename="package://nero_description/meshes/dae/link2.dae"/>
            </geometry>
        </visual>
        <collision>
            <origin xyz="0 0 0" rpy="0 0 0"/>
            <geometry>
                <mesh filename="package://nero_description/meshes/Link2.STL"/>
            </geometry>
        </collision>
    </link>
    <joint name="right_joint2" type="revolute">
        <origin xyz="0 0 0" rpy="1.5708 3.1415 0"/>
        <parent link="right_link1"/>
        <child link="right_link2"/>
        <axis xyz="0 0 1"/>
        <limit lower="-1.74" upper="1.74" effort="0" velocity="0"/>
    </joint>
    <link name="right_link3">
        <inertial>
            <origin xyz="0.00014 0.00211 -0.04853" rpy="0 0 0"/>
            <mass value="0.67"/>
            <inertia ixx="0.00342528" ixy="0.0" ixz="0.0" iyy="0.0033924" iyz="0.0" izz="0.00026169"/>
        </inertial>
        <visual>
            <origin xyz="0 0 0" rpy="0 0 0"/>
            <geometry>
                <mesh filename="package://nero_description/meshes/dae/link3.dae"/>
            </geometry>
        </visual>
        <collision>
            <origin xyz="0 0 0" rpy="0 0 0"/>
            <geometry>
                <mesh filename="package://nero_description/meshes/Link3.STL"/>
            </geometry>
        </collision>
    </link>
    <joint name="right_joint3" type="revolute">
        <origin xyz="0 -0.31 0" rpy="-1.5708 0 3.1416"/>
        <parent link="right_link2"/>
        <child link="right_link3"/>
        <axis xyz="0 0 1"/>
        <limit lower="-2.75" upper="2.75" effort="0" velocity="0"/>
    </joint>
    <link name="right_link4">
        <inertial>
            <origin xyz="-0.00013 -0.05482 0.00132" rpy="0 0 0"/>
            <mass value="0.41"/>
            <inertia ixx="0.00031331" ixy="0.0" ixz="0.0" iyy="0.00013204" iyz="0.0" izz="0.0002393"/>
        </inertial>
        <visual>
            <origin xyz="0 0 0" rpy="0 0 0"/>
            <geometry>
                <mesh filename="package://nero_description/meshes/dae/link4.dae"/>
            </geometry>
        </visual>
        <collision>
            <origin xyz="0 0 0" rpy="0 0 0"/>
            <geometry>
                <mesh filename="package://nero_description/meshes/Link4.STL"/>
            </geometry>
        </collision>
    </link>
    <joint name="right_joint4" type="revolute">
        <origin xyz="0 0 0" rpy="-1.5708 0 3.1416"/>
        <parent link="right_link3"/>
        <child link="right_link4"/>
        <axis xyz="0 0 1"/>
        <limit lower="-1.01" upper="2.14" effort="0" velocity="0"/>
    </joint>
    <link name="right_link5">
        <inertial>
            <origin xyz="0.00303 0.00617 -0.11778" rpy="0 0 0"/>
            <mass value="0.56"/>
            <inertia ixx="0.0008249" ixy="0.0" ixz="0.0" iyy="0.00078548" iyz="0.0" izz="0.00021015"/>
        </inertial>
        <visual>
            <origin xyz="0 0 0" rpy="0 0 0"/>
            <geometry>
                <mesh filename="package://nero_description/meshes/dae/link5.dae"/>
            </geometry>
        </visual>
        <collision>
            <origin xyz="0 0 0" rpy="0 0 0"/>
            <geometry>
                <mesh filename="package://nero_description/meshes/Link5.STL"/>
            </geometry>
        </collision>
    </link>
    <joint name="right_joint5" type="revolute">
        <origin xyz="0 -0.27001 0" rpy="1.5708 -1.5708 0"/>
        <parent link="right_link4"/>
        <child link="right_link5"/>
        <axis xyz="0 0 1"/>
        <limit lower="-2.75" upper="2.75" effort="0" velocity="0"/>
    </joint>
    <link name="right_link6">
        <inertial>
            <origin xyz="0.00014 -0.0027 -0.00025" rpy="0 0 0"/>
            <mass value="0.31"/>
            <inertia ixx="0.00008181" ixy="0.0" ixz="0.0" iyy="0.00007176" iyz="0.0" izz="0.00007906"/>
        </inertial>
        <visual>
            <origin xyz="0 0 0" rpy="0 0 0"/>
            <geometry>
                <mesh filename="package://nero_description/meshes/dae/link6.dae"/>
            </geometry>
        </visual>
        <collision>
            <origin xyz="0 0 0" rpy="0 0 0"/>
            <geometry>
                <mesh filename="package://nero_description/meshes/Link6.STL"/>
            </geometry>
        </collision>
    </link>
    <joint name="right_joint6" type="revolute">
        <origin xyz="0 0 0" rpy="1.5708 -1.5708 0"/>
        <parent link="right_link5"/>
        <child link="right_link6"/>
        <axis xyz="0 0 1"/>
        <limit lower="-0.73" upper="0.95" effort="0" velocity="0"/>
    </joint>
    <link name="right_link7">
        <inertial>
            <origin xyz="-0.00014000 -0.00010000 -0.00275000" rpy="0 0 0"/>
            <mass value="0.000001"/>
            <inertia ixx="1.1000000000000001e-07" ixy="0" ixz="0" iyy="1.1000000000000001e-07" iyz="0" izz="1.9999999999999999e-07"/>
        </inertial>
        <visual>
            <origin xyz="0 0 0" rpy="0 0 0"/>
            <geometry>
                <mesh filename="package://nero_description/meshes/dae/link7.dae"/>
            </geometry>
        </visual>
        <collision>
            <origin xyz="0 0 0" rpy="0 0 0"/>
            <geometry>
                <mesh filename="package://nero_description/meshes/Link7.STL"/>
            </geometry>
        </collision>
    </link>
    <joint name="right_joint7" type="revolute">
        <origin xyz="0 -0.0235 0" rpy="1.5708 0 0"/>
        <parent link="right_link6"/>
        <child link="right_link7"/>
        <axis xyz="0 0 1"/>
        <limit lower="-1.57" upper="1.57" effort="0" velocity="0"/>
    </joint>
    <link name="right_link8">
        <inertial>
            <origin xyz="-0.01208 -0.00025 0.00032" rpy="0 0 0"/>
            <mass value="0.05"/>
            <inertia ixx="2.697e-05" ixy="0" ixz="0" iyy="4.311e-05" iyz="0" izz="2.479e-05"/>
        </inertial>
        <visual>
            <origin xyz="0 0 0" rpy="-1.57 -1.57 -1.57"/>
            <geometry>
                <mesh filename="package://nero_description/meshes/stand_v1.dae"/>
            </geometry>
        </visual>
        <collision>
            <origin xyz="0 0 0" rpy="-1.57 -1.57 -1.57"/>
            <geometry>
                <mesh filename="package://nero_description/meshes/stand_v1.dae"/>
            </geometry>
        </collision>
    </link>
    <joint name="right_joint8" type="fixed">
        <origin xyz="0.033 0.00000000 -0.02350000" rpy="0 0 0"/>
        <parent link="right_link7"/>
        <child link="right_link8"/>
    </joint>

    <!-- Right Gripper Flange -->
    <link name="right_gripper_flange">
        <inertial>
            <origin xyz="0.0 0.0 -0.00032" rpy="0 0 0"/>
            <mass value="0.04771096"/>
            <inertia ixx="2.697e-05" ixy="0" ixz="0" iyy="4.311e-05" iyz="0" izz="2.479e-05"/>
        </inertial>
        <visual>
            <origin xyz="0 0 0" rpy="0 0 0"/>
            <geometry>
                <mesh filename="meshes/dae/gripper_flange.dae"/>
            </geometry>
        </visual>
        <collision>
            <origin xyz="0 0 0" rpy="0 0 0"/>
            <geometry>
                <mesh filename="meshes/gripper_flange.stl"/>
            </geometry>
        </collision>
    </link>
    <joint name="right_gripper_flange_joint" type="fixed">
        <origin xyz="0.032 0 -0.0235" rpy="-1.5708 0 -1.5708"/>
        <parent link="right_link7"/>
        <child link="right_gripper_flange"/>
    </joint>

    <!-- Right Gripper Base -->
    <link name="right_gripper_base">
        <inertial>
            <origin xyz="-0.000183807162235591 8.05033155577911E-05 0.0321436689908876" rpy="0 0 0"/>
            <mass value="0.45"/>
            <inertia ixx="0.00092934" ixy="0.00000034" ixz="-0.00000738" iyy="0.00071447" iyz="0.00000005" izz="0.00039442"/>
        </inertial>
        <visual>
            <origin xyz="0 0 0" rpy="0 0 0"/>
            <geometry>
                <mesh filename="meshes/dae/gripper_base.dae"/>
            </geometry>
        </visual>
        <collision>
            <origin xyz="0 0 0" rpy="0 0 0"/>
            <geometry>
                <mesh filename="meshes/gripper_base.stl"/>
            </geometry>
        </collision>
    </link>
    <joint name="right_gripper_base_joint" type="fixed">
        <origin xyz="0 0 0.0055" rpy="0 0 0"/>
        <parent link="right_gripper_flange"/>
        <child link="right_gripper_base"/>
    </joint>

    <!-- Right Gripper Link 1 -->
    <link name="right_gripper_link1">
        <inertial>
            <origin xyz="0.00065123185041968 -0.0491929869131989 0.00972258769184025" rpy="0 0 0"/>
            <mass value="0.025"/>
            <inertia ixx="0.00007371" ixy="-0.00000113" ixz="0.00000021" iyy="0.00000781" iyz="-0.00001372" izz="0.0000747"/>
        </inertial>
        <visual>
            <origin xyz="0 0 0" rpy="0 0 0"/>
            <geometry>
                <mesh filename="meshes/dae/gripper_link1.dae"/>
            </geometry>
        </visual>
        <collision>
            <origin xyz="0 0 0" rpy="0 0 0"/>
            <geometry>
                <mesh filename="meshes/gripper_link1.stl"/>
            </geometry>
        </collision>
    </link>
    <joint name="right_gripper_joint1" type="prismatic">
        <origin xyz="0 0 0.1358" rpy="1.5707963 0 3.1415926"/>
        <parent link="right_gripper_base"/>
        <child link="right_gripper_link1"/>
        <axis xyz="0 0 1"/>
        <limit lower="0" upper="0.05" effort="10" velocity="3"/>
    </joint>

    <!-- Right Gripper Link 2 -->
    <link name="right_gripper_link2">
        <inertial>
            <origin xyz="0.00065123185041968 -0.0491929869131989 0.00972258769184025" rpy="0 0 0"/>
            <mass value="0.025"/>
            <inertia ixx="0.00007371" ixy="-0.00000113" ixz="0.00000021" iyy="0.00000781" iyz="-0.00001372" izz="0.0000747"/>
        </inertial>
        <visual>
            <origin xyz="0 0 0" rpy="0 0 0"/>
            <geometry>
                <mesh filename="meshes/dae/gripper_link2.dae"/>
            </geometry>
        </visual>
        <collision>
            <origin xyz="0 0 0" rpy="0 0 0"/>
            <geometry>
                <mesh filename="meshes/gripper_link2.stl"/>
            </geometry>
        </collision>
    </link>
    <joint name="right_gripper_joint2" type="prismatic">
        <origin xyz="0 0 0.1358" rpy="1.5707963 0 0"/>
        <parent link="right_gripper_base"/>
        <child link="right_gripper_link2"/>
        <axis xyz="0 0 -1"/>
        <limit lower="-0.05" upper="0" effort="10" velocity="3"/>
    </joint>
</robot>
